[{"jsonrpc": "2.0", "method": "subscription", "params": {"channel": "book.BTC-PERPETUAL.none.20.agg2", "data": {"asks": [[65710.0, 17400.0], [65712.0, 200.0], [65712.5, 300.0], [65713.0, 90.0], [65721.0, 130.0], [65724.0, 8040.0], [65727.5, 110.0], [65734.0, 7777770.0], [65737.5, 140.0], [65739.5, 10000.0], [65742.0, 810.0], [65743.0, 23880.0], [65745.0, 10000.0], [65745.5, 160.0], [65746.0, 540.0], [65746.5, 20.0], [65747.0, 140.0], [65747.5, 30.0], [65751.0, 10000.0], [65755.0, 20.0]], "bids": [[65707.0, 7370.0], [65706.5, 1990.0], [65706.0, 36300.0], [65701.5, 4780.0], [65699.5, 73480.0], [65698.5, 66040.0], [65696.5, 2000.0], [65695.5, 10000.0], [65690.5, 10.0], [65690.0, 10000.0], [65684.0, 10000.0], [65678.5, 10000.0], [65673.0, 10000.0], [65668.5, 4755290.0], [65655.5, 100.0], [65626.0, 31970.0], [65540.5, 8008500.0], [65528.0, 2000.0], [65506.0, 180.0], [65410.5, 127910.0]], "instrument_name": "BTC-PERPETUAL", "change_id": 22068591201, "timestamp": 1712099569827}}, "_doc": "a8372a8f-cd99-4b56-a67a-d0abbe4fc6f0"}, {"jsonrpc": "2.0", "method": "subscription", "params": {"channel": "book.BTC-PERPETUAL.none.20.agg2", "data": {"asks": [[65710.0, 17400.0], [65712.5, 300.0], [65713.0, 90.0], [65721.0, 130.0], [65724.0, 8040.0], [65727.5, 110.0], [65734.0, 7777770.0], [65737.5, 140.0], [65739.5, 10000.0], [65742.0, 810.0], [65743.0, 23880.0], [65745.0, 10000.0], [65745.5, 160.0], [65746.0, 540.0], [65746.5, 20.0], [65747.0, 140.0], [65747.5, 30.0], [65751.0, 10000.0], [65755.0, 20.0], [65756.5, 10150.0]], "bids": [[65707.0, 7400.0], [65706.5, 1990.0], [65706.0, 36300.0], [65701.5, 4780.0], [65699.5, 73480.0], [65698.5, 66040.0], [65696.5, 2000.0], [65695.5, 10000.0], [65690.5, 10.0], [65690.0, 10000.0], [65684.0, 10000.0], [65678.5, 10000.0], [65673.0, 10000.0], [65668.5, 4755290.0], [65655.5, 100.0], [65626.0, 31970.0], [65540.5, 8008500.0], [65528.0, 2000.0], [65506.0, 180.0], [65410.5, 127910.0]], "instrument_name": "BTC-PERPETUAL", "change_id": 22068590811, "timestamp": 1712099568902}}, "_doc": "5fd651f2-4bc1-43d3-87f2-b389e041717a"}, {"jsonrpc": "2.0", "method": "subscription", "params": {"channel": "book.BTC-PERPETUAL.none.20.agg2", "data": {"asks": [[65710.0, 17420.0], [65712.5, 160.0], [65713.0, 90.0], [65721.0, 130.0], [65724.0, 8040.0], [65727.5, 110.0], [65734.0, 7777770.0], [65737.5, 140.0], [65739.5, 10000.0], [65742.0, 810.0], [65743.0, 23880.0], [65745.0, 10000.0], [65745.5, 160.0], [65746.0, 540.0], [65746.5, 20.0], [65747.0, 140.0], [65747.5, 30.0], [65751.0, 10000.0], [65755.0, 20.0], [65756.5, 10150.0]], "bids": [[65707.0, 7400.0], [65706.0, 38290.0], [65701.5, 4780.0], [65699.5, 73480.0], [65698.5, 66040.0], [65696.5, 2000.0], [65695.5, 10000.0], [65690.5, 10.0], [65690.0, 10000.0], [65684.0, 10000.0], [65678.5, 10000.0], [65673.0, 10000.0], [65668.5, 4755290.0], [65655.5, 100.0], [65626.0, 31970.0], [65540.5, 8008500.0], [65528.0, 2000.0], [65506.0, 180.0], [65410.5, 127910.0], [65339.5, 30.0]], "instrument_name": "BTC-PERPETUAL", "change_id": 22068590423, "timestamp": 1712099568000}}, "_doc": "7df9478a-172b-43ef-bfd5-dffc62ac1a7f"}, {"jsonrpc": "2.0", "method": "subscription", "params": {"channel": "book.BTC-PERPETUAL.none.20.agg2", "data": {"asks": [[65710.0, 17420.0], [65712.5, 160.0], [65713.0, 90.0], [65721.0, 130.0], [65724.0, 8040.0], [65727.5, 110.0], [65734.0, 7777770.0], [65737.5, 140.0], [65739.5, 10000.0], [65742.0, 810.0], [65743.0, 23880.0], [65745.0, 10000.0], [65745.5, 160.0], [65746.0, 540.0], [65746.5, 20.0], [65747.0, 140.0], [65747.5, 30.0], [65751.0, 10000.0], [65755.0, 20.0], [65756.5, 10150.0]], "bids": [[65707.0, 7420.0], [65706.0, 38290.0], [65699.5, 73480.0], [65698.5, 66040.0], [65696.5, 2000.0], [65695.5, 10000.0], [65690.5, 10.0], [65690.0, 10000.0], [65684.0, 10000.0], [65678.5, 10000.0], [65673.0, 10000.0], [65668.5, 4755290.0], [65655.5, 100.0], [65626.0, 31970.0], [65540.5, 8008500.0], [65528.0, 2000.0], [65506.0, 180.0], [65410.5, 127910.0], [65339.5, 30.0], [65261.0, 20.0]], "instrument_name": "BTC-PERPETUAL", "change_id": 22068589473, "timestamp": 1712099565782}}, "_doc": "e985ece5-cb14-41fd-9f5e-51fdd7b1e037"}, {"jsonrpc": "2.0", "method": "subscription", "params": {"channel": "book.BTC-PERPETUAL.none.20.agg2", "data": {"asks": [[65710.0, 17420.0], [65713.0, 90.0], [65721.0, 130.0], [65724.0, 8040.0], [65727.5, 110.0], [65734.0, 7777770.0], [65737.5, 140.0], [65739.5, 14950.0], [65742.0, 810.0], [65745.0, 10000.0], [65745.5, 160.0], [65746.0, 540.0], [65746.5, 20.0], [65747.0, 140.0], [65747.5, 30.0], [65751.0, 10000.0], [65755.0, 20.0], [65756.5, 10150.0], [65757.0, 120.0], [65762.0, 1990.0]], "bids": [[65707.0, 7440.0], [65706.0, 38290.0], [65699.5, 73480.0], [65698.5, 66040.0], [65696.5, 2000.0], [65695.5, 10000.0], [65690.5, 10.0], [65690.0, 10000.0], [65684.0, 10000.0], [65678.5, 10000.0], [65673.0, 10000.0], [65668.5, 4755290.0], [65655.5, 100.0], [65626.0, 31970.0], [65540.5, 8008500.0], [65528.0, 2000.0], [65506.0, 180.0], [65410.5, 127910.0], [65339.5, 30.0], [65261.0, 20.0]], "instrument_name": "BTC-PERPETUAL", "change_id": 22068589000, "timestamp": 1712099564678}}, "_doc": "5afdfde1-3de6-4512-98da-ef35bb8a4377"}, {"jsonrpc": "2.0", "method": "subscription", "params": {"channel": "book.BTC-PERPETUAL.none.20.agg2", "data": {"asks": [[65710.0, 17420.0], [65713.0, 90.0], [65721.0, 130.0], [65724.0, 8040.0], [65727.5, 110.0], [65734.0, 7777770.0], [65737.5, 140.0], [65739.5, 14950.0], [65742.0, 810.0], [65745.0, 10000.0], [65745.5, 160.0], [65746.0, 540.0], [65746.5, 20.0], [65747.0, 140.0], [65747.5, 30.0], [65751.0, 10000.0], [65755.0, 20.0], [65756.5, 10150.0], [65757.0, 120.0], [65762.0, 1990.0]], "bids": [[65707.0, 7990.0], [65706.0, 38290.0], [65699.5, 73480.0], [65698.5, 66040.0], [65696.5, 2000.0], [65695.5, 10000.0], [65690.5, 10.0], [65690.0, 10000.0], [65684.0, 10000.0], [65678.5, 10000.0], [65673.0, 10000.0], [65668.5, 4755290.0], [65655.5, 100.0], [65626.0, 31970.0], [65540.5, 8008500.0], [65528.0, 2000.0], [65506.0, 180.0], [65410.5, 127910.0], [65339.5, 30.0], [65261.0, 20.0]], "instrument_name": "BTC-PERPETUAL", "change_id": 22068588600, "timestamp": 1712099563689}}, "_doc": "7cf795d9-4572-47cc-a288-d3faa685f0f3"}, {"jsonrpc": "2.0", "method": "subscription", "params": {"channel": "book.BTC-PERPETUAL.none.20.agg2", "data": {"asks": [[65710.0, 17890.0], [65721.0, 130.0], [65724.0, 8040.0], [65727.5, 110.0], [65734.0, 7777770.0], [65737.5, 140.0], [65739.5, 14950.0], [65742.0, 810.0], [65745.0, 10000.0], [65745.5, 160.0], [65746.0, 540.0], [65746.5, 20.0], [65747.0, 140.0], [65747.5, 30.0], [65751.0, 10000.0], [65755.0, 20.0], [65756.5, 10150.0], [65757.0, 120.0], [65762.0, 1990.0], [65762.5, 10000.0]], "bids": [[65708.5, 990.0], [65707.0, 7990.0], [65706.0, 36300.0], [65699.5, 73480.0], [65698.5, 66040.0], [65696.5, 2000.0], [65695.5, 10000.0], [65690.5, 10.0], [65690.0, 10000.0], [65684.0, 10000.0], [65678.5, 10000.0], [65673.0, 10000.0], [65668.5, 4755290.0], [65655.5, 100.0], [65626.0, 31970.0], [65540.5, 8008500.0], [65528.0, 2000.0], [65506.0, 180.0], [65410.5, 127910.0], [65339.5, 30.0]], "instrument_name": "BTC-PERPETUAL", "change_id": 22068588286, "timestamp": 1712099562972}}, "_doc": "fbf01044-d16a-441e-acfc-5c10f05a0ba6"}, {"jsonrpc": "2.0", "method": "subscription", "params": {"channel": "book.BTC-PERPETUAL.none.20.agg2", "data": {"asks": [[65709.0, 80.0], [65710.0, 18200.0], [65721.0, 130.0], [65724.0, 8040.0], [65727.5, 110.0], [65734.0, 7777770.0], [65737.5, 140.0], [65739.5, 14950.0], [65742.0, 810.0], [65745.0, 10000.0], [65745.5, 160.0], [65746.0, 540.0], [65746.5, 20.0], [65747.0, 140.0], [65747.5, 30.0], [65751.0, 10000.0], [65755.0, 20.0], [65756.5, 10150.0], [65757.0, 120.0], [65762.0, 1990.0]], "bids": [[65708.5, 1150.0], [65707.0, 7990.0], [65706.0, 36300.0], [65699.5, 73480.0], [65698.5, 66040.0], [65696.5, 2000.0], [65695.5, 10000.0], [65690.5, 10.0], [65690.0, 10000.0], [65684.0, 10000.0], [65678.5, 10000.0], [65673.0, 10000.0], [65668.5, 4755290.0], [65655.5, 100.0], [65626.0, 31970.0], [65540.5, 8008500.0], [65528.0, 2000.0], [65506.0, 180.0], [65410.5, 127910.0], [65339.5, 30.0]], "instrument_name": "BTC-PERPETUAL", "change_id": 22068587913, "timestamp": 1712099562127}}, "_doc": "d41a9be1-504c-4d70-87d7-9b1037385938"}, {"jsonrpc": "2.0", "method": "subscription", "params": {"channel": "book.BTC-PERPETUAL.none.20.agg2", "data": {"asks": [[65710.0, 24810.0], [65714.5, 20.0], [65721.0, 130.0], [65724.0, 8040.0], [65727.5, 110.0], [65730.5, 100.0], [65734.0, 7777770.0], [65737.5, 140.0], [65739.0, 4690.0], [65739.5, 10000.0], [65742.0, 810.0], [65745.0, 10000.0], [65745.5, 160.0], [65746.0, 540.0], [65746.5, 20.0], [65747.0, 140.0], [65747.5, 30.0], [65751.0, 10000.0], [65755.0, 20.0], [65756.5, 10150.0]], "bids": [[65709.5, 50.0], [65708.5, 1250.0], [65707.0, 7990.0], [65706.0, 36300.0], [65699.5, 73480.0], [65698.5, 66040.0], [65696.5, 2000.0], [65695.5, 10000.0], [65690.5, 10.0], [65690.0, 10000.0], [65684.0, 10000.0], [65678.5, 10000.0], [65673.0, 10000.0], [65668.5, 4755290.0], [65655.5, 100.0], [65626.0, 31970.0], [65540.5, 8008500.0], [65528.0, 2000.0], [65506.0, 180.0], [65410.5, 127910.0]], "instrument_name": "BTC-PERPETUAL", "change_id": 22068587376, "timestamp": 1712099560927}}, "_doc": "7938918e-5a44-4fc5-9dd2-00c2b2c768a0"}, {"jsonrpc": "2.0", "method": "subscription", "params": {"channel": "book.BTC-PERPETUAL.none.20.agg2", "data": {"asks": [[65710.0, 24980.0], [65714.5, 20.0], [65721.0, 130.0], [65724.0, 8040.0], [65727.5, 110.0], [65730.5, 100.0], [65734.0, 7777770.0], [65737.5, 140.0], [65739.0, 4690.0], [65739.5, 10000.0], [65742.0, 810.0], [65745.0, 10000.0], [65745.5, 160.0], [65746.0, 540.0], [65746.5, 20.0], [65747.0, 140.0], [65747.5, 30.0], [65751.0, 10000.0], [65755.0, 20.0], [65756.5, 10150.0]], "bids": [[65708.5, 1310.0], [65707.0, 7990.0], [65706.0, 36300.0], [65699.5, 73480.0], [65698.5, 33020.0], [65696.5, 2000.0], [65695.5, 10000.0], [65690.5, 10.0], [65690.0, 10000.0], [65684.0, 10000.0], [65678.5, 10000.0], [65673.0, 10000.0], [65668.5, 4755290.0], [65655.5, 100.0], [65626.0, 31970.0], [65540.5, 8008500.0], [65528.0, 2000.0], [65506.0, 180.0], [65410.5, 127910.0], [65339.5, 30.0]], "instrument_name": "BTC-PERPETUAL", "change_id": 22068586956, "timestamp": 1712099560050}}, "_doc": "a86ac1b5-0d2f-4222-aa22-eac986955a28"}, {"jsonrpc": "2.0", "method": "subscription", "params": {"channel": "book.BTC-PERPETUAL.none.20.agg2", "data": {"asks": [[65710.0, 25020.0], [65714.5, 20.0], [65721.0, 130.0], [65724.0, 8040.0], [65727.5, 110.0], [65730.5, 100.0], [65734.0, 7777770.0], [65737.5, 140.0], [65739.0, 4690.0], [65739.5, 10000.0], [65742.0, 810.0], [65745.0, 10000.0], [65745.5, 160.0], [65746.0, 540.0], [65746.5, 20.0], [65747.0, 140.0], [65747.5, 30.0], [65751.0, 10000.0], [65755.0, 20.0], [65756.5, 10150.0]], "bids": [[65709.5, 40.0], [65708.5, 1420.0], [65707.0, 7990.0], [65706.0, 36300.0], [65699.5, 73480.0], [65698.5, 33020.0], [65696.5, 2000.0], [65695.5, 10000.0], [65690.5, 10.0], [65690.0, 10000.0], [65684.0, 10000.0], [65678.5, 10000.0], [65673.0, 10000.0], [65668.5, 4755290.0], [65655.5, 100.0], [65626.0, 31970.0], [65540.5, 8008500.0], [65528.0, 2000.0], [65506.0, 180.0], [65410.5, 127910.0]], "instrument_name": "BTC-PERPETUAL", "change_id": 22068586527, "timestamp": 1712099559052}}, "_doc": "948d0bb6-482c-4eb1-88e4-31d2c374585f"}, {"jsonrpc": "2.0", "method": "subscription", "params": {"channel": "book.BTC-PERPETUAL.none.20.agg2", "data": {"asks": [[65710.0, 25190.0], [65714.5, 20.0], [65721.0, 130.0], [65724.0, 8040.0], [65727.5, 110.0], [65730.5, 100.0], [65734.0, 7777770.0], [65737.5, 140.0], [65739.0, 4690.0], [65739.5, 10000.0], [65742.0, 810.0], [65745.5, 10160.0], [65746.0, 540.0], [65746.5, 20.0], [65747.0, 140.0], [65747.5, 30.0], [65751.0, 10000.0], [65755.0, 20.0], [65756.5, 10150.0], [65757.0, 120.0]], "bids": [[65708.5, 1460.0], [65707.0, 7990.0], [65706.0, 36300.0], [65699.5, 73480.0], [65698.5, 33020.0], [65696.5, 2000.0], [65695.5, 10000.0], [65690.5, 10.0], [65690.0, 10000.0], [65684.0, 10000.0], [65679.0, 10000.0], [65673.0, 10000.0], [65668.5, 4755290.0], [65655.5, 100.0], [65626.0, 31970.0], [65540.5, 8008500.0], [65528.0, 2000.0], [65506.0, 180.0], [65410.5, 127910.0], [65339.5, 30.0]], "instrument_name": "BTC-PERPETUAL", "change_id": 22068586114, "timestamp": 1712099557983}}, "_doc": "847f37b0-d4fe-4cab-9ae2-253840503c99"}, {"jsonrpc": "2.0", "method": "subscription", "params": {"channel": "book.BTC-PERPETUAL.none.20.agg2", "data": {"asks": [[65709.0, 50.0], [65710.0, 25190.0], [65714.5, 20.0], [65721.0, 130.0], [65724.0, 8040.0], [65727.5, 110.0], [65730.5, 100.0], [65734.0, 7777770.0], [65737.5, 140.0], [65739.0, 4690.0], [65739.5, 10000.0], [65742.0, 810.0], [65745.5, 10160.0], [65746.0, 540.0], [65746.5, 20.0], [65747.0, 140.0], [65747.5, 30.0], [65751.5, 10000.0], [65755.0, 20.0], [65756.5, 10150.0]], "bids": [[65708.5, 1430.0], [65707.0, 7990.0], [65706.0, 36300.0], [65699.5, 73480.0], [65698.5, 33020.0], [65696.5, 2000.0], [65695.5, 10000.0], [65690.5, 10.0], [65690.0, 10000.0], [65684.0, 10000.0], [65679.0, 10000.0], [65673.0, 10000.0], [65668.5, 4755290.0], [65655.5, 100.0], [65626.0, 31970.0], [65540.5, 8008500.0], [65528.0, 2000.0], [65506.0, 180.0], [65410.5, 127910.0], [65339.5, 30.0]], "instrument_name": "BTC-PERPETUAL", "change_id": 22068585746, "timestamp": 1712099557087}}, "_doc": "a899d912-7a26-4c6c-a63e-10b43e244d13"}, {"jsonrpc": "2.0", "method": "subscription", "params": {"channel": "book.BTC-PERPETUAL.none.20.agg2", "data": {"asks": [[65710.0, 25190.0], [65714.5, 20.0], [65721.0, 130.0], [65724.0, 8040.0], [65727.5, 110.0], [65730.5, 100.0], [65734.0, 7777770.0], [65737.5, 140.0], [65739.0, 4690.0], [65740.0, 10000.0], [65742.0, 810.0], [65745.5, 10160.0], [65746.0, 540.0], [65746.5, 20.0], [65747.0, 140.0], [65747.5, 30.0], [65751.5, 10000.0], [65755.0, 20.0], [65756.5, 10150.0], [65757.0, 120.0]], "bids": [[65708.5, 1460.0], [65707.0, 7990.0], [65706.0, 36300.0], [65699.5, 73480.0], [65698.5, 33020.0], [65696.5, 2000.0], [65695.5, 10000.0], [65690.5, 10.0], [65690.0, 10000.0], [65684.5, 10000.0], [65679.0, 10000.0], [65673.0, 10000.0], [65668.5, 4755290.0], [65655.5, 100.0], [65626.0, 31970.0], [65540.5, 8008500.0], [65528.0, 2000.0], [65506.0, 180.0], [65410.5, 127910.0], [65339.5, 30.0]], "instrument_name": "BTC-PERPETUAL", "change_id": 22068585267, "timestamp": 1712099555991}}, "_doc": "64b17440-0902-4bf0-9596-e02bd4e5e423"}, {"jsonrpc": "2.0", "method": "subscription", "params": {"channel": "book.BTC-PERPETUAL.none.20.agg2", "data": {"asks": [[65709.0, 90.0], [65710.0, 25270.0], [65714.5, 20.0], [65721.0, 130.0], [65724.0, 8040.0], [65727.5, 110.0], [65730.5, 100.0], [65734.0, 7777770.0], [65737.5, 140.0], [65739.0, 4690.0], [65740.0, 10000.0], [65742.0, 810.0], [65745.5, 10160.0], [65746.0, 540.0], [65746.5, 20.0], [65747.0, 140.0], [65747.5, 30.0], [65751.5, 10000.0], [65755.0, 20.0], [65756.5, 150.0]], "bids": [[65708.5, 1460.0], [65707.0, 7990.0], [65706.0, 36300.0], [65699.5, 73480.0], [65696.5, 2000.0], [65696.0, 10000.0], [65690.5, 10.0], [65690.0, 10000.0], [65684.5, 10000.0], [65679.0, 10000.0], [65673.0, 10000.0], [65668.5, 4755290.0], [65655.5, 100.0], [65626.0, 31970.0], [65540.5, 8008500.0], [65528.0, 2000.0], [65506.0, 180.0], [65410.5, 127910.0], [65339.5, 30.0], [65261.0, 20.0]], "instrument_name": "BTC-PERPETUAL", "change_id": 22068584872, "timestamp": 1712099555124}}, "_doc": "bb2cb37e-ff38-45f9-a2d0-f79414febc3c"}, {"jsonrpc": "2.0", "method": "subscription", "params": {"channel": "book.BTC-PERPETUAL.none.20.agg2", "data": {"asks": [[65710.0, 25270.0], [65721.0, 130.0], [65724.0, 8040.0], [65727.5, 110.0], [65730.5, 100.0], [65734.0, 7777770.0], [65737.5, 140.0], [65740.0, 10000.0], [65742.0, 810.0], [65743.5, 57190.0], [65745.5, 10160.0], [65746.0, 540.0], [65746.5, 20.0], [65747.0, 140.0], [65747.5, 30.0], [65751.5, 10000.0], [65755.0, 20.0], [65756.5, 150.0], [65757.0, 10120.0], [65762.0, 1990.0]], "bids": [[65708.5, 1630.0], [65707.0, 7990.0], [65706.0, 36300.0], [65699.5, 73480.0], [65696.5, 2000.0], [65696.0, 10000.0], [65690.5, 10.0], [65690.0, 10000.0], [65684.5, 10000.0], [65679.0, 10000.0], [65673.0, 10000.0], [65668.5, 4755290.0], [65655.5, 100.0], [65626.0, 31970.0], [65540.5, 8008500.0], [65528.0, 2000.0], [65506.0, 180.0], [65410.5, 127910.0], [65339.5, 30.0], [65261.0, 20.0]], "instrument_name": "BTC-PERPETUAL", "change_id": 22068584360, "timestamp": 1712099553990}}, "_doc": "b20976ed-0310-4c45-9afd-178df49da96b"}, {"jsonrpc": "2.0", "method": "subscription", "params": {"channel": "book.BTC-PERPETUAL.none.20.agg2", "data": {"asks": [[65710.0, 25300.0], [65721.0, 130.0], [65724.0, 8040.0], [65727.5, 110.0], [65730.5, 100.0], [65734.0, 7777770.0], [65737.5, 140.0], [65740.0, 10000.0], [65742.0, 810.0], [65743.5, 57190.0], [65745.5, 10160.0], [65746.0, 540.0], [65746.5, 20.0], [65747.0, 140.0], [65747.5, 30.0], [65751.5, 10000.0], [65755.0, 20.0], [65756.5, 150.0], [65757.0, 10120.0], [65762.0, 1990.0]], "bids": [[65708.5, 1650.0], [65707.0, 7990.0], [65706.0, 36300.0], [65699.5, 73480.0], [65696.5, 2000.0], [65696.0, 10000.0], [65690.5, 10.0], [65690.0, 10000.0], [65684.5, 10000.0], [65679.0, 10000.0], [65673.0, 10000.0], [65668.5, 4755290.0], [65655.5, 100.0], [65626.0, 31970.0], [65540.5, 8008500.0], [65528.0, 2000.0], [65506.0, 180.0], [65410.5, 127910.0], [65339.5, 30.0], [65261.0, 20.0]], "instrument_name": "BTC-PERPETUAL", "change_id": 22068583843, "timestamp": 1712099552696}}, "_doc": "3eeb9735-6760-4a73-90f2-5a34287c70ba"}, {"jsonrpc": "2.0", "method": "subscription", "params": {"channel": "book.BTC-PERPETUAL.none.20.agg2", "data": {"asks": [[65710.0, 25380.0], [65721.0, 130.0], [65724.0, 8040.0], [65727.5, 110.0], [65730.5, 100.0], [65734.0, 7777770.0], [65737.5, 140.0], [65740.0, 10000.0], [65742.0, 810.0], [65743.5, 57190.0], [65745.5, 10160.0], [65746.0, 540.0], [65746.5, 20.0], [65747.0, 140.0], [65747.5, 30.0], [65751.5, 10000.0], [65755.0, 20.0], [65756.5, 150.0], [65757.0, 10120.0], [65762.0, 1990.0]], "bids": [[65709.5, 60.0], [65708.5, 1650.0], [65707.0, 7990.0], [65706.0, 36300.0], [65699.5, 73480.0], [65696.5, 2000.0], [65696.0, 10000.0], [65690.5, 10010.0], [65684.5, 10000.0], [65679.0, 10000.0], [65673.5, 10000.0], [65668.5, 4755290.0], [65655.5, 100.0], [65626.0, 31970.0], [65540.5, 8008500.0], [65528.0, 2000.0], [65506.0, 180.0], [65410.5, 127910.0], [65339.5, 30.0], [65261.0, 20.0]], "instrument_name": "BTC-PERPETUAL", "change_id": 22068583583, "timestamp": 1712099552092}}, "_doc": "d4dfdd0e-e49b-41dd-bb95-0782f6811c44"}, {"jsonrpc": "2.0", "method": "subscription", "params": {"channel": "book.BTC-PERPETUAL.none.20.agg2", "data": {"asks": [[65710.0, 25380.0], [65721.0, 130.0], [65724.0, 8040.0], [65727.5, 110.0], [65730.5, 100.0], [65734.0, 7777770.0], [65737.5, 140.0], [65739.5, 4950.0], [65740.0, 10000.0], [65742.0, 810.0], [65745.5, 10160.0], [65746.0, 540.0], [65746.5, 20.0], [65747.0, 140.0], [65747.5, 30.0], [65751.5, 10000.0], [65755.0, 20.0], [65756.5, 150.0], [65757.0, 10120.0], [65762.0, 1990.0]], "bids": [[65709.5, 180.0], [65708.5, 1650.0], [65707.0, 7990.0], [65706.0, 36300.0], [65699.5, 73480.0], [65696.5, 2000.0], [65696.0, 10000.0], [65690.5, 10010.0], [65684.5, 10000.0], [65679.0, 10000.0], [65673.5, 10000.0], [65668.5, 4755290.0], [65655.5, 100.0], [65626.0, 31970.0], [65540.5, 8008500.0], [65528.0, 2000.0], [65506.0, 180.0], [65410.5, 127910.0], [65339.5, 30.0], [65261.0, 20.0]], "instrument_name": "BTC-PERPETUAL", "change_id": 22068583266, "timestamp": 1712099551342}}, "_doc": "1d8688f4-6cd5-4f46-88b3-d535c313e0da"}, {"jsonrpc": "2.0", "id": 9479043403, "result": ["book.BTC-PERPETUAL.none.20.agg2"], "usIn": 1712099551527929, "usOut": 1712099551528117, "usDiff": 188, "testnet": true, "_doc": "c0f5a8c4-0cdd-4da1-ba9b-e00b3de978a9"}, {"jsonrpc": "2.0", "method": "subscription", "params": {"channel": "book.BTC-PERPETUAL.none.20.agg2", "data": {"asks": [[65827.0, 7562290.0], [65831.0, 10000.0], [65836.0, 10000.0], [65839.0, 10000.0], [65843.0, 170.0], [65848.0, 10070.0], [65849.0, 40.0], [65849.5, 170.0], [65850.0, 10.0], [65853.0, 10000.0], [65884.5, 22890.0], [65896.0, 24200.0], [65897.5, 24200.0], [65898.0, 97100.0], [65898.5, 12100.0], [65908.5, 230.0], [65912.0, 80.0], [65914.0, 56000.0], [65915.0, 180.0], [65915.5, 40.0]], "bids": [[65817.0, 76970.0], [65814.0, 40.0], [65807.0, 190.0], [65787.0, 10000.0], [65783.5, 7990.0], [65780.5, 10000.0], [65779.5, 1990.0], [65772.0, 10000.0], [65769.0, 10000.0], [65761.5, 4891770.0], [65745.5, 10.0], [65723.0, 100.0], [65712.5, 30.0], [65710.0, 50.0], [65709.5, 170.0], [65633.5, 8008500.0], [65585.0, 2000.0], [65506.0, 180.0], [65339.5, 30.0], [65261.0, 20.0]], "instrument_name": "BTC-PERPETUAL", "change_id": 22068196667, "timestamp": 1712098694633}}, "_doc": "f7f68319-0a22-41be-a14d-b6bdaae11951"}, {"jsonrpc": "2.0", "method": "subscription", "params": {"channel": "book.BTC-PERPETUAL.none.20.agg2", "data": {"asks": [[65825.5, 9100.0], [65827.0, 7562490.0], [65831.5, 10000.0], [65839.0, 10000.0], [65842.5, 10000.0], [65843.0, 170.0], [65848.0, 10070.0], [65849.0, 40.0], [65849.5, 170.0], [65850.0, 10.0], [65884.5, 22890.0], [65896.0, 24200.0], [65897.5, 24200.0], [65898.0, 97100.0], [65898.5, 12100.0], [65908.5, 230.0], [65912.0, 80.0], [65914.0, 56000.0], [65915.0, 180.0], [65915.5, 40.0]], "bids": [[65817.0, 77040.0], [65814.0, 40.0], [65783.5, 7990.0], [65781.5, 10000.0], [65775.5, 10000.0], [65772.0, 10000.0], [65766.5, 10000.0], [65761.5, 4891770.0], [65745.5, 10.0], [65723.0, 100.0], [65712.5, 30.0], [65710.0, 50.0], [65709.5, 170.0], [65689.5, 2000.0], [65633.5, 8008500.0], [65506.0, 180.0], [65339.5, 30.0], [65275.5, 10.0], [65261.0, 20.0], [65254.5, 100.0]], "instrument_name": "BTC-PERPETUAL", "change_id": 22068196102, "timestamp": 1712098693635}}, "_doc": "2201add8-c167-4ffe-ab5d-390ddf2e3913"}, {"jsonrpc": "2.0", "method": "subscription", "params": {"channel": "book.BTC-PERPETUAL.none.20.agg2", "data": {"asks": [[65825.5, 9550.0], [65827.0, 7562490.0], [65831.5, 10000.0], [65839.0, 10000.0], [65842.5, 10000.0], [65843.0, 170.0], [65848.0, 10070.0], [65849.0, 40.0], [65849.5, 170.0], [65850.0, 10.0], [65884.5, 22890.0], [65896.0, 24200.0], [65897.5, 24200.0], [65898.0, 97100.0], [65898.5, 12100.0], [65908.5, 230.0], [65912.0, 80.0], [65914.0, 56000.0], [65915.0, 180.0], [65915.5, 40.0]], "bids": [[65817.0, 77650.0], [65814.0, 40.0], [65781.5, 10000.0], [65780.5, 9980.0], [65775.5, 10000.0], [65772.0, 10000.0], [65766.5, 10000.0], [65761.5, 4891770.0], [65745.5, 10.0], [65723.0, 100.0], [65712.5, 30.0], [65710.0, 50.0], [65709.5, 170.0], [65689.5, 2000.0], [65633.5, 8008500.0], [65506.0, 180.0], [65339.5, 30.0], [65275.5, 10.0], [65261.0, 20.0], [65254.5, 100.0]], "instrument_name": "BTC-PERPETUAL", "change_id": 22068195626, "timestamp": 1712098692617}}, "_doc": "1d4c2732-8e06-464e-a951-65ac5da7119f"}, {"jsonrpc": "2.0", "method": "subscription", "params": {"channel": "book.BTC-PERPETUAL.none.20.agg2", "data": {"asks": [[65825.5, 10000.0], [65827.0, 7562490.0], [65831.5, 10000.0], [65839.0, 10000.0], [65842.5, 10000.0], [65843.0, 170.0], [65848.0, 10070.0], [65849.0, 40.0], [65849.5, 170.0], [65850.0, 10.0], [65884.5, 22890.0], [65896.0, 24200.0], [65897.5, 24200.0], [65898.0, 97100.0], [65898.5, 12100.0], [65908.5, 230.0], [65912.0, 80.0], [65914.0, 56000.0], [65915.0, 180.0], [65915.5, 40.0]], "bids": [[65817.0, 160.0], [65784.0, 9530.0], [65780.5, 9980.0], [65775.5, 10000.0], [65772.0, 10000.0], [65766.5, 10000.0], [65761.5, 4891770.0], [65745.5, 10.0], [65723.0, 100.0], [65712.5, 30.0], [65710.0, 50.0], [65709.5, 170.0], [65689.5, 2000.0], [65633.5, 8008500.0], [65506.0, 180.0], [65339.5, 30.0], [65275.5, 10.0], [65261.0, 20.0], [65254.5, 100.0], [65249.5, 110.0]], "instrument_name": "BTC-PERPETUAL", "change_id": 22068195160, "timestamp": 1712098691619}}, "_doc": "7e83b15d-83d2-422a-98b9-a21dc8ac2e67"}, {"jsonrpc": "2.0", "method": "subscription", "params": {"channel": "book.BTC-PERPETUAL.none.20.agg2", "data": {"asks": [[65820.5, 30.0], [65828.5, 10000.0], [65834.0, 10000.0], [65843.0, 7562760.0], [65845.0, 10000.0], [65848.0, 70.0], [65849.0, 40.0], [65849.5, 170.0], [65850.0, 10.0], [65850.5, 10000.0], [65856.0, 10000.0], [65884.5, 22890.0], [65896.0, 24200.0], [65897.5, 24200.0], [65898.0, 97100.0], [65898.5, 12100.0], [65908.5, 230.0], [65912.0, 80.0], [65914.0, 56000.0], [65915.0, 180.0]], "bids": [[65787.5, 1950.0], [65784.5, 7990.0], [65784.0, 20000.0], [65777.5, 4881770.0], [65775.5, 10000.0], [65766.5, 10000.0], [65761.5, 10000.0], [65745.5, 10.0], [65723.0, 100.0], [65712.5, 30.0], [65710.0, 50.0], [65709.5, 170.0], [65689.5, 2000.0], [65633.5, 8008500.0], [65506.0, 180.0], [65339.5, 30.0], [65275.5, 10.0], [65261.0, 20.0], [65254.5, 100.0], [65249.5, 110.0]], "instrument_name": "BTC-PERPETUAL", "change_id": 22068194685, "timestamp": 1712098690640}}, "_doc": "bad668b7-a301-44a3-88d6-f490ac918356"}, {"jsonrpc": "2.0", "method": "subscription", "params": {"channel": "book.BTC-PERPETUAL.none.20.agg2", "data": {"asks": [[65821.5, 180.0], [65831.0, 9910.0], [65837.0, 10000.0], [65843.0, 7562760.0], [65845.0, 10000.0], [65848.0, 70.0], [65849.0, 40.0], [65849.5, 170.0], [65850.0, 10.0], [65850.5, 10000.0], [65856.0, 10000.0], [65884.5, 22890.0], [65896.0, 24200.0], [65897.5, 24200.0], [65898.0, 97100.0], [65898.5, 12100.0], [65908.5, 230.0], [65912.0, 80.0], [65914.0, 56000.0], [65915.0, 180.0]], "bids": [[65791.0, 1170.0], [65790.5, 7990.0], [65789.5, 10000.0], [65784.0, 10000.0], [65777.5, 4881770.0], [65775.5, 10000.0], [65772.5, 10000.0], [65766.5, 10000.0], [65745.5, 10.0], [65723.0, 100.0], [65712.5, 30.0], [65710.0, 50.0], [65709.5, 170.0], [65689.5, 2000.0], [65649.5, 8008500.0], [65506.0, 180.0], [65339.5, 30.0], [65275.5, 10.0], [65261.0, 20.0], [65254.5, 100.0]], "instrument_name": "BTC-PERPETUAL", "change_id": 22068194146, "timestamp": 1712098689561}}, "_doc": "aaf75772-b45d-4ca0-988a-a6d9f1916d60"}, {"jsonrpc": "2.0", "method": "subscription", "params": {"channel": "book.BTC-PERPETUAL.none.20.agg2", "data": {"asks": [[65822.0, 190.0], [65833.5, 9880.0], [65839.5, 10000.0], [65843.0, 7562760.0], [65845.0, 10000.0], [65848.0, 70.0], [65849.0, 40.0], [65849.5, 170.0], [65850.0, 10.0], [65850.5, 10000.0], [65856.0, 10000.0], [65884.5, 22890.0], [65896.0, 24200.0], [65897.5, 24200.0], [65898.0, 97100.0], [65898.5, 12100.0], [65908.5, 230.0], [65912.0, 80.0], [65914.0, 56000.0], [65915.0, 180.0]], "bids": [[65791.0, 1680.0], [65790.5, 7990.0], [65789.5, 10000.0], [65784.0, 10000.0], [65778.0, 10000.0], [65777.5, 4881770.0], [65772.5, 10000.0], [65766.5, 10000.0], [65745.5, 10.0], [65723.0, 100.0], [65712.5, 30.0], [65710.0, 50.0], [65709.5, 170.0], [65689.5, 2000.0], [65649.5, 8008500.0], [65506.0, 180.0], [65339.5, 30.0], [65275.5, 10.0], [65261.0, 20.0], [65254.5, 100.0]], "instrument_name": "BTC-PERPETUAL", "change_id": 22068193658, "timestamp": 1712098688612}}, "_doc": "dc6e5de5-932a-4366-bb06-aee82238a53b"}, {"jsonrpc": "2.0", "method": "subscription", "params": {"channel": "book.BTC-PERPETUAL.none.20.agg2", "data": {"asks": [[65822.5, 30.0], [65835.0, 9980.0], [65839.5, 10000.0], [65840.5, 10000.0], [65843.0, 7562760.0], [65846.5, 10000.0], [65848.0, 70.0], [65849.0, 40.0], [65849.5, 170.0], [65850.0, 10.0], [65865.5, 10000.0], [65884.5, 22890.0], [65896.0, 24200.0], [65897.5, 24200.0], [65898.0, 97100.0], [65898.5, 12100.0], [65908.5, 230.0], [65912.0, 80.0], [65914.0, 56000.0], [65915.0, 180.0]], "bids": [[65791.0, 1920.0], [65790.5, 17990.0], [65781.5, 10000.0], [65779.5, 10000.0], [65777.5, 4881770.0], [65773.5, 10000.0], [65762.5, 10000.0], [65745.5, 10.0], [65723.0, 100.0], [65712.5, 30.0], [65710.0, 50.0], [65709.5, 170.0], [65689.5, 2000.0], [65649.5, 8008500.0], [65506.0, 180.0], [65339.5, 30.0], [65275.5, 10.0], [65261.0, 20.0], [65254.5, 100.0], [65249.5, 110.0]], "instrument_name": "BTC-PERPETUAL", "change_id": 22068193163, "timestamp": 1712098687638}}, "_doc": "e0af9875-9371-4230-bf06-c8491df87860"}, {"jsonrpc": "2.0", "method": "subscription", "params": {"channel": "book.BTC-PERPETUAL.none.20.agg2", "data": {"asks": [[65821.0, 100.0], [65835.0, 10000.0], [65840.5, 10000.0], [65843.0, 7562760.0], [65848.0, 70.0], [65849.0, 40.0], [65849.5, 170.0], [65850.0, 10.0], [65854.0, 10000.0], [65858.5, 10000.0], [65865.5, 10000.0], [65884.5, 22890.0], [65896.0, 24200.0], [65897.5, 24200.0], [65898.0, 97100.0], [65898.5, 12100.0], [65908.5, 230.0], [65912.0, 80.0], [65914.0, 56000.0], [65915.0, 180.0]], "bids": [[65820.5, 40.0], [65789.0, 7990.0], [65787.0, 1990.0], [65786.5, 10000.0], [65785.0, 10000.0], [65781.5, 10000.0], [65777.5, 4881770.0], [65776.0, 10000.0], [65774.5, 10000.0], [65745.5, 10.0], [65723.0, 100.0], [65712.5, 30.0], [65710.0, 50.0], [65709.5, 170.0], [65689.5, 2000.0], [65649.5, 8008500.0], [65506.0, 180.0], [65339.5, 30.0], [65275.5, 10.0], [65261.0, 20.0]], "instrument_name": "BTC-PERPETUAL", "change_id": 22068192674, "timestamp": 1712098686631}}, "_doc": "0eb718c3-2a72-47d2-90ba-582343ad354a"}, {"jsonrpc": "2.0", "method": "subscription", "params": {"channel": "book.BTC-PERPETUAL.none.20.agg2", "data": {"asks": [[65837.5, 10000.0], [65843.0, 7562760.0], [65847.5, 10000.0], [65848.0, 70.0], [65849.0, 40.0], [65849.5, 170.0], [65850.0, 10.0], [65854.0, 10000.0], [65858.5, 10000.0], [65865.5, 10000.0], [65884.5, 22890.0], [65896.0, 24200.0], [65897.5, 24200.0], [65898.0, 97100.0], [65898.5, 12100.0], [65908.5, 230.0], [65912.0, 80.0], [65914.0, 56000.0], [65915.0, 180.0], [65915.5, 40.0]], "bids": [[65793.0, 9990.0], [65786.5, 10000.0], [65781.5, 10000.0], [65777.5, 4881770.0], [65776.0, 10000.0], [65774.5, 10000.0], [65745.5, 10.0], [65723.0, 100.0], [65712.5, 30.0], [65710.0, 50.0], [65709.5, 170.0], [65649.5, 8008500.0], [65605.0, 2000.0], [65506.0, 180.0], [65339.5, 30.0], [65275.5, 10.0], [65261.0, 20.0], [65254.5, 100.0], [65249.5, 110.0], [65247.5, 170.0]], "instrument_name": "BTC-PERPETUAL", "change_id": 22068192130, "timestamp": 1712098685555}}, "_doc": "fd5b4d8a-00ac-4af4-b5c9-5309eaa97d65"}, {"jsonrpc": "2.0", "method": "subscription", "params": {"channel": "book.BTC-PERPETUAL.none.20.agg2", "data": {"asks": [[65834.5, 10000.0], [65843.0, 7562760.0], [65847.5, 10000.0], [65848.0, 70.0], [65849.0, 40.0], [65849.5, 170.0], [65850.0, 10.0], [65854.0, 10000.0], [65858.5, 10000.0], [65865.5, 10000.0], [65884.5, 15000.0], [65896.0, 24200.0], [65896.5, 2890.0], [65897.5, 24200.0], [65898.0, 97100.0], [65898.5, 12100.0], [65908.5, 230.0], [65912.0, 80.0], [65914.0, 56000.0], [65915.0, 180.0]], "bids": [[65792.5, 1950.0], [65790.5, 10000.0], [65786.5, 17900.0], [65786.0, 10000.0], [65777.5, 4891770.0], [65774.5, 10000.0], [65745.5, 10.0], [65723.0, 100.0], [65712.5, 30.0], [65710.0, 50.0], [65709.5, 170.0], [65649.5, 8008500.0], [65605.0, 2000.0], [65506.0, 180.0], [65339.5, 30.0], [65275.5, 10.0], [65261.0, 20.0], [65254.5, 100.0], [65249.5, 110.0], [65247.5, 170.0]], "instrument_name": "BTC-PERPETUAL", "change_id": 22068191720, "timestamp": 1712098684916}}, "_doc": "73048cc8-c318-4a5f-b2f6-d91ddda68059"}, {"jsonrpc": "2.0", "id": 6877092705, "result": ["book.BTC-PERPETUAL.none.20.agg2"], "usIn": 1712098685055736, "usOut": 1712098685055966, "usDiff": 230, "testnet": true, "_doc": "ec146733-b11c-4509-ab46-882f1787b4f2"}, {"jsonrpc": "2.0", "method": "subscription", "params": {"channel": "book.BTC-PERPETUAL.none.20.agg2", "data": {"asks": [[65770.0, 80.0], [65777.5, 655670.0], [65791.5, 10000.0], [65795.0, 1990.0], [65795.5, 7990.0], [65797.5, 10000.0], [65803.0, 10000.0], [65808.5, 10000.0], [65819.5, 10000.0], [65822.5, 7777770.0], [65825.5, 10.0], [65829.5, 150.0], [65881.5, 50.0], [65886.5, 31970.0], [65940.5, 80.0], [65944.0, 210.0], [65950.5, 7776880.0], [65953.5, 70.0], [65954.5, 50.0], [65956.0, 10.0]], "bids": [[65757.0, 5810850.0], [65747.5, 10000.0], [65742.0, 10000.0], [65738.0, 10000.0], [65733.0, 6790.0], [65730.5, 10000.0], [65725.0, 10000.0], [65723.0, 100.0], [65721.0, 10.0], [65717.5, 20.0], [65713.0, 600.0], [65712.5, 30.0], [65712.0, 50.0], [65710.0, 50.0], [65709.5, 170.0], [65700.0, 12030.0], [65699.0, 112000.0], [65697.5, 20060.0], [65695.0, 1120.0], [65694.5, 12000.0]], "instrument_name": "BTC-PERPETUAL", "change_id": 22067866556, "timestamp": 1712097973712}}, "_doc": "aab039f7-dc4a-4751-a0ba-c8a723bdb53c"}, {"jsonrpc": "2.0", "method": "subscription", "params": {"channel": "book.BTC-PERPETUAL.none.20.agg2", "data": {"asks": [[65770.0, 150.0], [65777.5, 655810.0], [65791.5, 10000.0], [65795.0, 1990.0], [65795.5, 7990.0], [65803.0, 20000.0], [65810.0, 10000.0], [65819.5, 10000.0], [65822.5, 7777770.0], [65825.5, 10.0], [65829.5, 150.0], [65881.5, 50.0], [65886.5, 31970.0], [65940.5, 80.0], [65944.0, 210.0], [65950.5, 7776880.0], [65953.5, 70.0], [65954.5, 50.0], [65956.0, 10.0], [65985.0, 90.0]], "bids": [[65757.0, 5810970.0], [65747.5, 10000.0], [65741.5, 10000.0], [65738.0, 10000.0], [65733.0, 6790.0], [65732.5, 10000.0], [65726.0, 10000.0], [65723.0, 100.0], [65721.0, 10.0], [65717.5, 20.0], [65713.0, 600.0], [65712.5, 30.0], [65712.0, 50.0], [65710.0, 50.0], [65709.5, 170.0], [65700.0, 12030.0], [65699.0, 112000.0], [65697.5, 20060.0], [65695.0, 1120.0], [65694.5, 12000.0]], "instrument_name": "BTC-PERPETUAL", "change_id": 22067866041, "timestamp": 1712097972656}}, "_doc": "ec43bf55-e309-41cb-836f-e831c023bc70"}, {"jsonrpc": "2.0", "method": "subscription", "params": {"channel": "book.BTC-PERPETUAL.none.20.agg2", "data": {"asks": [[65777.5, 655990.0], [65791.5, 10000.0], [65795.0, 1990.0], [65795.5, 7990.0], [65803.0, 20000.0], [65810.0, 10000.0], [65819.5, 10000.0], [65822.5, 7777770.0], [65825.5, 10.0], [65829.5, 150.0], [65881.5, 50.0], [65886.5, 31970.0], [65940.5, 80.0], [65944.0, 210.0], [65950.5, 7776880.0], [65953.5, 70.0], [65954.5, 50.0], [65956.0, 10.0], [65985.0, 90.0], [65987.5, 90.0]], "bids": [[65757.0, 5811150.0], [65747.5, 10000.0], [65741.5, 10000.0], [65738.0, 10000.0], [65733.0, 6790.0], [65732.5, 10000.0], [65726.0, 10000.0], [65723.0, 100.0], [65721.0, 10.0], [65717.5, 20.0], [65713.0, 600.0], [65712.5, 30.0], [65712.0, 50.0], [65710.0, 50.0], [65709.5, 170.0], [65700.0, 12030.0], [65699.0, 112000.0], [65697.5, 20060.0], [65695.0, 1120.0], [65694.5, 12000.0]], "instrument_name": "BTC-PERPETUAL", "change_id": 22067865597, "timestamp": 1712097971648}}, "_doc": "f05b126a-f06b-4cdd-943f-95691cdd756c"}, {"jsonrpc": "2.0", "method": "subscription", "params": {"channel": "book.BTC-PERPETUAL.none.20.agg2", "data": {"asks": [[65777.5, 655990.0], [65791.5, 10000.0], [65795.0, 1990.0], [65795.5, 7990.0], [65803.0, 20000.0], [65810.0, 10000.0], [65819.5, 10000.0], [65822.5, 7777770.0], [65825.5, 10.0], [65829.5, 150.0], [65881.5, 50.0], [65886.5, 31970.0], [65940.5, 80.0], [65944.0, 210.0], [65950.5, 7776880.0], [65953.5, 70.0], [65954.5, 50.0], [65956.0, 10.0], [65985.0, 90.0], [65987.5, 90.0]], "bids": [[65757.0, 5811350.0], [65747.5, 10000.0], [65741.5, 10000.0], [65738.0, 10000.0], [65733.0, 6790.0], [65732.5, 10000.0], [65726.0, 10000.0], [65723.0, 100.0], [65721.0, 10.0], [65717.5, 20.0], [65713.0, 600.0], [65712.5, 30.0], [65712.0, 50.0], [65710.0, 50.0], [65709.5, 170.0], [65700.0, 12030.0], [65699.0, 112000.0], [65697.5, 20060.0], [65695.0, 1120.0], [65694.5, 12000.0]], "instrument_name": "BTC-PERPETUAL", "change_id": 22067865124, "timestamp": 1712097970561}}, "_doc": "dbed24db-2f09-4f00-be68-d37f328b9fe6"}, {"jsonrpc": "2.0", "method": "subscription", "params": {"channel": "book.BTC-PERPETUAL.none.20.agg2", "data": {"asks": [[65757.5, 975510.0], [65777.5, 656120.0], [65795.0, 1990.0], [65795.5, 7990.0], [65797.0, 10000.0], [65803.0, 10000.0], [65808.5, 10000.0], [65810.0, 10000.0], [65819.5, 10000.0], [65822.5, 7777770.0], [65825.5, 10.0], [65829.5, 150.0], [65881.5, 50.0], [65886.5, 31970.0], [65940.5, 80.0], [65944.0, 210.0], [65953.5, 70.0], [65954.5, 50.0], [65956.0, 10.0], [65985.0, 90.0]], "bids": [[65757.0, 5811470.0], [65751.0, 10000.0], [65745.5, 10000.0], [65738.0, 10000.0], [65733.0, 6790.0], [65732.5, 10000.0], [65726.0, 10000.0], [65723.0, 100.0], [65721.0, 10.0], [65717.5, 20.0], [65713.0, 600.0], [65712.5, 30.0], [65712.0, 50.0], [65710.0, 50.0], [65709.5, 170.0], [65700.0, 12030.0], [65699.0, 112000.0], [65697.5, 20060.0], [65695.0, 1120.0], [65694.5, 12000.0]], "instrument_name": "BTC-PERPETUAL", "change_id": 22067864734, "timestamp": 1712097969679}}, "_doc": "2c60c666-0144-4a4b-965c-0969c09b8e0a"}, {"jsonrpc": "2.0", "method": "subscription", "params": {"channel": "book.BTC-PERPETUAL.none.20.agg2", "data": {"asks": [[65757.5, 40.0], [65777.5, 656180.0], [65795.0, 1990.0], [65795.5, 7990.0], [65797.0, 10000.0], [65803.0, 10000.0], [65808.5, 10000.0], [65814.0, 10000.0], [65819.5, 10000.0], [65822.5, 7777770.0], [65825.5, 10.0], [65829.5, 150.0], [65881.5, 50.0], [65886.5, 31970.0], [65940.5, 80.0], [65944.0, 210.0], [65953.5, 70.0], [65954.5, 50.0], [65956.0, 10.0], [65959.5, 7776950.0]], "bids": [[65757.0, 5811610.0], [65751.0, 10000.0], [65745.5, 10000.0], [65741.5, 10000.0], [65734.0, 10000.0], [65733.0, 6790.0], [65728.0, 10000.0], [65723.0, 100.0], [65721.0, 10.0], [65717.5, 20.0], [65713.0, 600.0], [65712.5, 30.0], [65712.0, 50.0], [65710.0, 50.0], [65709.5, 170.0], [65700.0, 12030.0], [65699.0, 112000.0], [65697.5, 20060.0], [65695.0, 1120.0], [65694.5, 12000.0]], "instrument_name": "BTC-PERPETUAL", "change_id": 22067864263, "timestamp": 1712097968712}}, "_doc": "a3a1369d-d2ef-45a5-8273-e0f51bfd1e72"}, {"jsonrpc": "2.0", "method": "subscription", "params": {"channel": "book.BTC-PERPETUAL.none.20.agg2", "data": {"asks": [[65777.5, 656180.0], [65795.0, 1990.0], [65795.5, 7990.0], [65797.0, 10000.0], [65803.0, 10000.0], [65808.5, 10000.0], [65814.0, 10000.0], [65819.5, 10000.0], [65822.5, 7777770.0], [65825.5, 10.0], [65829.5, 150.0], [65881.5, 50.0], [65886.5, 31970.0], [65940.5, 80.0], [65944.0, 210.0], [65953.5, 70.0], [65954.5, 50.0], [65956.0, 10.0], [65959.5, 7776950.0], [65985.0, 90.0]], "bids": [[65757.0, 5811730.0], [65756.0, 10000.0], [65747.5, 10000.0], [65741.5, 10000.0], [65739.0, 10000.0], [65733.5, 10000.0], [65733.0, 6790.0], [65723.0, 100.0], [65721.0, 10.0], [65717.5, 20.0], [65713.0, 600.0], [65712.5, 30.0], [65712.0, 50.0], [65710.0, 50.0], [65709.5, 170.0], [65700.0, 12030.0], [65699.0, 112000.0], [65697.5, 20060.0], [65695.0, 1120.0], [65694.5, 12000.0]], "instrument_name": "BTC-PERPETUAL", "change_id": 22067863804, "timestamp": 1712097967699}}, "_doc": "e0eb5489-82ae-4fda-a818-661acea80492"}, {"jsonrpc": "2.0", "method": "subscription", "params": {"channel": "book.BTC-PERPETUAL.none.20.agg2", "data": {"asks": [[65777.5, 656490.0], [65795.0, 1990.0], [65795.5, 7990.0], [65797.0, 10000.0], [65803.0, 10000.0], [65810.5, 10000.0], [65817.0, 10000.0], [65823.0, 10000.0], [65825.5, 10.0], [65829.5, 150.0], [65831.5, 7777770.0], [65881.5, 50.0], [65886.5, 31970.0], [65940.5, 80.0], [65944.0, 210.0], [65953.5, 70.0], [65954.5, 50.0], [65956.0, 10.0], [65959.5, 7776950.0], [65985.0, 90.0]], "bids": [[65762.0, 10.0], [65757.0, 5811870.0], [65756.0, 10000.0], [65747.5, 10000.0], [65741.5, 10000.0], [65739.0, 10000.0], [65733.5, 10000.0], [65733.0, 6790.0], [65723.0, 100.0], [65721.0, 10.0], [65717.5, 20.0], [65713.0, 600.0], [65712.5, 30.0], [65712.0, 50.0], [65710.0, 50.0], [65709.5, 170.0], [65700.0, 12030.0], [65699.0, 112000.0], [65697.5, 20060.0], [65695.0, 1120.0]], "instrument_name": "BTC-PERPETUAL", "change_id": 22067863355, "timestamp": 1712097966628}}, "_doc": "c3abd5bc-456b-401e-a8a0-141dd4c0e366"}, {"jsonrpc": "2.0", "method": "subscription", "params": {"channel": "book.BTC-PERPETUAL.none.20.agg2", "data": {"asks": [[65777.5, 656490.0], [65795.0, 1990.0], [65795.5, 7990.0], [65800.0, 10000.0], [65806.0, 10000.0], [65810.5, 10000.0], [65817.0, 10000.0], [65823.0, 10000.0], [65825.5, 10.0], [65829.5, 150.0], [65831.5, 7777770.0], [65881.5, 50.0], [65886.5, 31970.0], [65940.5, 80.0], [65944.0, 210.0], [65953.5, 70.0], [65954.5, 50.0], [65956.0, 10.0], [65959.5, 7776950.0], [65985.0, 90.0]], "bids": [[65766.0, 5811870.0], [65762.0, 10.0], [65756.0, 10000.0], [65750.5, 10000.0], [65744.5, 10000.0], [65739.0, 10000.0], [65733.5, 10000.0], [65733.0, 6790.0], [65723.0, 100.0], [65721.0, 10.0], [65717.5, 20.0], [65713.0, 600.0], [65712.5, 30.0], [65712.0, 50.0], [65710.0, 50.0], [65709.5, 170.0], [65700.0, 12030.0], [65699.0, 112000.0], [65697.5, 20060.0], [65695.0, 1120.0]], "instrument_name": "BTC-PERPETUAL", "change_id": 22067862784, "timestamp": 1712097965441}}, "_doc": "0a61fab0-9c27-49a0-9d50-859fb27df6d7"}, {"jsonrpc": "2.0", "method": "subscription", "params": {"channel": "book.BTC-PERPETUAL.none.20.agg2", "data": {"asks": [[65777.5, 656490.0], [65795.0, 1990.0], [65795.5, 7990.0], [65800.0, 10000.0], [65806.0, 10000.0], [65810.5, 10000.0], [65817.0, 10000.0], [65823.0, 10000.0], [65825.5, 10.0], [65829.5, 150.0], [65831.5, 7777770.0], [65881.5, 50.0], [65886.5, 31970.0], [65940.5, 80.0], [65944.0, 210.0], [65953.5, 70.0], [65954.5, 50.0], [65956.0, 10.0], [65959.5, 7776950.0], [65985.0, 90.0]], "bids": [[65766.0, 5811870.0], [65762.0, 10.0], [65756.0, 10000.0], [65750.5, 10000.0], [65744.5, 10000.0], [65739.0, 10000.0], [65733.5, 10000.0], [65733.0, 6790.0], [65723.0, 100.0], [65721.0, 10.0], [65717.5, 20.0], [65713.0, 600.0], [65712.5, 30.0], [65712.0, 50.0], [65710.0, 50.0], [65709.5, 170.0], [65700.0, 12030.0], [65699.0, 112000.0], [65697.5, 20060.0], [65695.0, 1120.0]], "instrument_name": "BTC-PERPETUAL", "change_id": 22067862411, "timestamp": 1712097964661}}, "_doc": "d9141b42-1e9d-4510-b3f6-05d50b0d87c6"}, {"jsonrpc": "2.0", "method": "subscription", "params": {"channel": "book.BTC-PERPETUAL.none.20.agg2", "data": {"asks": [[65777.5, 656490.0], [65795.0, 1990.0], [65795.5, 7990.0], [65800.0, 10000.0], [65806.0, 10000.0], [65810.5, 10000.0], [65817.0, 10000.0], [65823.0, 10000.0], [65825.5, 10.0], [65829.5, 150.0], [65831.5, 7777770.0], [65881.5, 50.0], [65886.5, 31970.0], [65940.5, 80.0], [65944.0, 210.0], [65953.5, 70.0], [65954.5, 50.0], [65956.0, 10.0], [65959.5, 7776950.0], [65985.0, 90.0]], "bids": [[65766.0, 5811970.0], [65762.0, 10.0], [65756.0, 10000.0], [65750.5, 10000.0], [65744.5, 10000.0], [65739.0, 10000.0], [65733.5, 10000.0], [65733.0, 6790.0], [65723.0, 100.0], [65721.0, 10.0], [65717.5, 20.0], [65713.0, 600.0], [65712.5, 30.0], [65712.0, 50.0], [65710.0, 50.0], [65709.5, 170.0], [65699.0, 112000.0], [65697.5, 18540.0], [65695.0, 1120.0], [65694.5, 12000.0]], "instrument_name": "BTC-PERPETUAL", "change_id": 22067861825, "timestamp": 1712097963343}}, "_doc": "2b7ce9bf-f25e-4a96-825d-a86c4df762d7"}, {"jsonrpc": "2.0", "method": "subscription", "params": {"channel": "book.BTC-PERPETUAL.none.20.agg2", "data": {"asks": [[65777.5, 656610.0], [65795.0, 1990.0], [65795.5, 7990.0], [65800.0, 10000.0], [65806.0, 10000.0], [65810.5, 10000.0], [65817.0, 10000.0], [65823.0, 10000.0], [65825.5, 10.0], [65829.5, 150.0], [65831.5, 7777770.0], [65881.5, 50.0], [65886.5, 31970.0], [65940.5, 80.0], [65944.0, 210.0], [65953.5, 70.0], [65954.5, 50.0], [65956.0, 10.0], [65959.5, 7776950.0], [65985.0, 90.0]], "bids": [[65766.0, 5811990.0], [65762.0, 10.0], [65756.0, 10000.0], [65750.5, 10000.0], [65744.5, 10000.0], [65739.0, 10000.0], [65733.5, 10000.0], [65733.0, 6790.0], [65723.0, 100.0], [65721.0, 10.0], [65717.5, 20.0], [65713.0, 600.0], [65712.5, 30.0], [65712.0, 50.0], [65710.0, 50.0], [65709.5, 170.0], [65699.0, 112000.0], [65697.5, 18540.0], [65695.0, 1120.0], [65694.5, 12000.0]], "instrument_name": "BTC-PERPETUAL", "change_id": 22067861517, "timestamp": 1712097962614}}, "_doc": "eef814df-a184-4720-bb87-1dfa496094b3"}, {"jsonrpc": "2.0", "id": 9759389330, "result": ["book.BTC-PERPETUAL.none.20.agg2"], "usIn": 1712097962803126, "usOut": 1712097962803285, "usDiff": 159, "testnet": true, "_doc": "9049c714-864c-46de-97f8-9ee3b736fc9d"}]